2022-05-16 12:19:40,479 ERROR: Exception on /user/Xanders [GET] [in /Library/Frameworks/Python.framework/Versions/3.9/lib/python3.9/site-packages/flask/app.py:1457]
Traceback (most recent call last):
  File "/Library/Frameworks/Python.framework/Versions/3.9/lib/python3.9/site-packages/sqlalchemy/engine/base.py", line 1802, in _execute_context
    self.dialect.do_execute(
  File "/Library/Frameworks/Python.framework/Versions/3.9/lib/python3.9/site-packages/sqlalchemy/engine/default.py", line 732, in do_execute
    cursor.execute(statement, parameters)
sqlite3.OperationalError: no such column: user.age

The above exception was the direct cause of the following exception:

Traceback (most recent call last):
  File "/Library/Frameworks/Python.framework/Versions/3.9/lib/python3.9/site-packages/flask/app.py", line 2073, in wsgi_app
    response = self.full_dispatch_request()
  File "/Library/Frameworks/Python.framework/Versions/3.9/lib/python3.9/site-packages/flask/app.py", line 1518, in full_dispatch_request
    rv = self.handle_user_exception(e)
  File "/Library/Frameworks/Python.framework/Versions/3.9/lib/python3.9/site-packages/flask/app.py", line 1514, in full_dispatch_request
    rv = self.preprocess_request()
  File "/Library/Frameworks/Python.framework/Versions/3.9/lib/python3.9/site-packages/flask/app.py", line 1857, in preprocess_request
    rv = self.ensure_sync(before_func)()
  File "/Users/alexandertsekov/Desktop/microblog_copy/app/routes.py", line 14, in before_request
    if current_user.is_authenticated:
  File "/Library/Frameworks/Python.framework/Versions/3.9/lib/python3.9/site-packages/werkzeug/local.py", line 432, in __get__
    obj = instance._get_current_object()
  File "/Library/Frameworks/Python.framework/Versions/3.9/lib/python3.9/site-packages/werkzeug/local.py", line 554, in _get_current_object
    return self.__local()  # type: ignore
  File "/Library/Frameworks/Python.framework/Versions/3.9/lib/python3.9/site-packages/flask_login/utils.py", line 25, in <lambda>
    current_user = LocalProxy(lambda: _get_user())
  File "/Library/Frameworks/Python.framework/Versions/3.9/lib/python3.9/site-packages/flask_login/utils.py", line 359, in _get_user
    current_app.login_manager._load_user()
  File "/Library/Frameworks/Python.framework/Versions/3.9/lib/python3.9/site-packages/flask_login/login_manager.py", line 355, in _load_user
    user = self._user_callback(user_id)
  File "/Users/alexandertsekov/Desktop/microblog_copy/app/models.py", line 85, in load_user
    return User.query.get(int(id))
  File "<string>", line 2, in get
  File "/Library/Frameworks/Python.framework/Versions/3.9/lib/python3.9/site-packages/sqlalchemy/util/deprecations.py", line 401, in warned
    return fn(*args, **kwargs)
  File "/Library/Frameworks/Python.framework/Versions/3.9/lib/python3.9/site-packages/sqlalchemy/orm/query.py", line 943, in get
    return self._get_impl(ident, loading.load_on_pk_identity)
  File "/Library/Frameworks/Python.framework/Versions/3.9/lib/python3.9/site-packages/sqlalchemy/orm/query.py", line 947, in _get_impl
    return self.session._get_impl(
  File "/Library/Frameworks/Python.framework/Versions/3.9/lib/python3.9/site-packages/sqlalchemy/orm/session.py", line 2892, in _get_impl
    return db_load_fn(
  File "/Library/Frameworks/Python.framework/Versions/3.9/lib/python3.9/site-packages/sqlalchemy/orm/loading.py", line 530, in load_on_pk_identity
    session.execute(
  File "/Library/Frameworks/Python.framework/Versions/3.9/lib/python3.9/site-packages/sqlalchemy/orm/session.py", line 1692, in execute
    result = conn._execute_20(statement, params or {}, execution_options)
  File "/Library/Frameworks/Python.framework/Versions/3.9/lib/python3.9/site-packages/sqlalchemy/engine/base.py", line 1614, in _execute_20
    return meth(self, args_10style, kwargs_10style, execution_options)
  File "/Library/Frameworks/Python.framework/Versions/3.9/lib/python3.9/site-packages/sqlalchemy/sql/elements.py", line 325, in _execute_on_connection
    return connection._execute_clauseelement(
  File "/Library/Frameworks/Python.framework/Versions/3.9/lib/python3.9/site-packages/sqlalchemy/engine/base.py", line 1481, in _execute_clauseelement
    ret = self._execute_context(
  File "/Library/Frameworks/Python.framework/Versions/3.9/lib/python3.9/site-packages/sqlalchemy/engine/base.py", line 1845, in _execute_context
    self._handle_dbapi_exception(
  File "/Library/Frameworks/Python.framework/Versions/3.9/lib/python3.9/site-packages/sqlalchemy/engine/base.py", line 2026, in _handle_dbapi_exception
    util.raise_(
  File "/Library/Frameworks/Python.framework/Versions/3.9/lib/python3.9/site-packages/sqlalchemy/util/compat.py", line 207, in raise_
    raise exception
  File "/Library/Frameworks/Python.framework/Versions/3.9/lib/python3.9/site-packages/sqlalchemy/engine/base.py", line 1802, in _execute_context
    self.dialect.do_execute(
  File "/Library/Frameworks/Python.framework/Versions/3.9/lib/python3.9/site-packages/sqlalchemy/engine/default.py", line 732, in do_execute
    cursor.execute(statement, parameters)
sqlalchemy.exc.OperationalError: (sqlite3.OperationalError) no such column: user.age
[SQL: SELECT user.id AS user_id, user.username AS user_username, user.email AS user_email, user.password_hash AS user_password_hash, user.about_me AS user_about_me, user.last_seen AS user_last_seen, user.age AS user_age, user.grade AS user_grade 
FROM user 
WHERE user.id = ?]
[parameters: (4,)]
(Background on this error at: https://sqlalche.me/e/14/e3q8)
